Workbook

Sheet М_июль 1 цк
A2: Предельные уровни нерегулируемых цен на электрическую энергию (мощность), поставляемую АО "Мосэнергосбыт" потребителям
A3: с максимальной мощностью энергопринимающих устройств не менее 10 МВт
A4: г. Москва
A5: Июль 2025 г.
A7: I. Первая ценовая категория для объемов покупки электрической энергии (мощности), учет которых осуществляется в целом за расчетный период
A9: 1. Предельный уровень нерегулируемых цен, руб./МВт∙ч без НДС
A11: № п/п | B11: Группа потребителей | C11: Уровень напряжения
C12: ВН | D12: СН I | E12: СН II | F12: НН
A13: 1.1. | B13: Прочие потребители
A14: 1.1.1. | B14: Иные прочие потребители | C14: =C15+C16+C17+C19+C18 -> 4968.4 | D14: =D15+D16+D17+D19+D18 -> 5758.33 | E14: =E15+E16+E17+E19+E18 -> 6410.34 | F14: =F15+F16+F17+F19+F18 -> 8086.5
B15: - средневзв. стоимость э/э (м) | C15: 3602.47 | D15: =C15 -> 3602.47 | E15: =C15 -> 3602.47 | F15: =C15 -> 3602.47
B16: - услуги по передаче | C16: 1283.66 | D16: 2073.59 | E16: 2725.6 | F16: 4401.76
B17: - сбытовая надбавка ГП | C17: 75.85 | D17: =C17 -> 75.85 | E17: =C17 -> 75.85 | F17: =C17 -> 75.85
B18: - плата за услуги по управлению изменением режима потребления электрической энергии | C18: 1.07 | D18: 1.07 | E18: 1.07 | F18: 1.07
B19: - инфраструктурные платежи | C19: 5.35 | D19: =C19 -> 5.35 | E19: =C19 -> 5.35 | F19: =C19 -> 5.35
A20: 1.1.2. | B20: Потребители, рассчитывающиеся по договорам купли-продажи | C20: =C21+C22+C24+C23 -> 3684.74 | D20: =D21+D22+D24+D23 -> 3684.74 | E20: =E21+E22+E24+E23 -> 3684.74 | F20: =F21+F22+F24+F23 -> 3684.74
B21: - средневзв. стоимость э/э (м) | C21: =C15 -> 3602.47 | D21: =C21 -> 3602.47 | E21: =C21 -> 3602.47 | F21: =C21 -> 3602.47
B22: - сбытовая надбавка ГП | C22: =C17 -> 75.85 | D22: =C22 -> 75.85 | E22: =C22 -> 75.85 | F22: =C22 -> 75.85
B23: - плата за услуги по управлению изменением режима потребления электрической энергии | C23: 1.07 | D23: 1.07 | E23: 1.07 | F23: 1.07
B24: - инфраструктурные платежи | C24: =C19 -> 5.35 | D24: =C24 -> 5.35 | E24: =C24 -> 5.35 | F24: =C24 -> 5.35
A27: 2. | B27: Средневзвешенная нерегулируемая цена на электрическую энергию (мощность), используемая для расчета предельного уровня нерегулируемых цен для первой ценовой категории, без НДС, руб./МВт∙ч | E27: 3602.47
A28: 3. | B28: Составляющие расчета средневзвешенной нерегулируемой цены на электрическую энергию (мощность), используемой для расчета предельного уровня нерегулируемых цен для первой ценовой категории:
A29: а) | B29: средневзвешенная нерегулируемая цена на электрическую энергию на оптовом рынке, руб./МВт∙ч | E29: 2324,93
A30: б) | B30: средневзвешенная нерегулируемая цена на мощность на оптовом рынке, руб./МВт | E30: 937404,45
A31: в) | B31: коэффициент оплаты мощности потребителями (покупателями), осуществляющими расчеты по первой ценовой категории, 1/час | E31: 0.0013628526
A32: г) | B32: объем фактического пикового потребления гарантирующего поставщика на оптовом рынке, МВт | E32: 12653.047
A33: д) | B33: величина мощности, соответствующей покупке электрической энергии гарантирующим поставщиком у производителей электрической энергии (мощности) на розничных рынках, МВт | E33: 8.244
A34: е) | B34: сумма величин мощности, оплачиваемой на розничном рынке потребителями (покупателями), осуществляющими расчеты по второй - шестой ценовым категориям, МВт | E34: 5425.2309
B35: в том числе:
B36: – по второй ценовой категории, МВт | E36: 31.37
B37: – по третьей ценовой категории, МВт | E37: 3055.548
B38: – по четвертой ценовой категории, МВт | E38: 1954.9029
B39: – по пятой ценовой категории, МВт | E39: 24.143838
B40: – по шестой ценовой категории, МВт | E40: 359.26613
A41: ж) | B41: объем потребления мощности населением и приравненными к нему категориями потребителей, МВт | E41: 3942.223
A42: з) | B42: объем потребления электрической энергии потребителями (покупателями), осуществляющими расчеты по второй ценовой категории, МВт∙ч | E42: 13059.656
B43: в том числе:
B44: для трех зон суток, МВт∙ч | E44: 10179.74
B45: – по ночной зоне суток, МВт∙ч | E45: 3314.096
B46: – по полупиковой зоне суток, МВт∙ч | E46: 4121.4071
...

Sheet М_июль 2 цк
A2: ='М_июль 1 цк'!A2 -> Предельные уровни нерегулируемых цен на электрическую энергию (мощность), поставляемую АО "Мосэнергосбыт" потребителям
A3: ='М_июль 1 цк'!A3 -> с максимальной мощностью энергопринимающих устройств не менее 10 МВт
A4: ='М_июль 1 цк'!A4 -> г. Москва
A5: ='М_июль 1 цк'!A5 -> Июль 2025 г.
A7: II. Вторая ценовая категория для объемов покупки электрической энергии (мощности), учет которых осуществляется по зонам суток расчетного периода
A9: 1. Предельный уровень нерегулируемых цен для трех зон суток, руб./МВт∙ч без НДС
A11: № п/п | B11: Группа потребителей | C11: Уровень напряжения
C12: ВН | D12: СН I | E12: СН II | F12: НН
A13: 1.1. | B13: Прочие потребители
A14: 1.1.1. | B14: Иные прочие потребители
A15: 1.1.1.1. | B15: ночная зона | C15: =C16+C17+C18+C20+C19 -> 2571.64 | D15: =D16+D17+D18+D20+D19 -> 3361.57 | E15: =E16+E17+E18+E20+E19 -> 4013.58 | F15: =F16+F17+F18+F20+F19 -> 5689.74
B16: - средневзв. стоимость э/э (м) | C16: 1205.71 | D16: =C16 -> 1205.71 | E16: =C16 -> 1205.71 | F16: =C16 -> 1205.71
B17: - услуги по передаче | C17: 1283.66 | D17: 2073.59 | E17: 2725.6 | F17: 4401.76
B18: - сбытовая надбавка ГП | C18: 75.85 | D18: =C18 -> 75.85 | E18: =C18 -> 75.85 | F18: =C18 -> 75.85
B19: - плата за услуги по управлению изменением режима потребления электрической энергии | C19: 1.07 | D19: 1.07 | E19: 1.07 | F19: 1.07
B20: - инфраструктурные платежи | C20: 5.35 | D20: =C20 -> 5.35 | E20: =C20 -> 5.35 | F20: =C20 -> 5.35
A21: 1.1.1.2. | B21: полупиковая зона | C21: =C22+C23+C24+C26+C25 -> 5487.87 | D21: =D22+D23+D24+D26+D25 -> 6277.8 | E21: =E22+E23+E24+E26+E25 -> 6929.81 | F21: =F22+F23+F24+F26+F25 -> 8605.97
B22: - средневзв. стоимость э/э (м) | C22: 4121.94 | D22: =C22 -> 4121.94 | E22: =C22 -> 4121.94 | F22: =C22 -> 4121.94
B23: - услуги по передаче | C23: =C17 -> 1283.66 | D23: =D17 -> 2073.59 | E23: =E17 -> 2725.6 | F23: =F17 -> 4401.76
B24: - сбытовая надбавка ГП | C24: 75.85 | D24: =C24 -> 75.85 | E24: =C24 -> 75.85 | F24: =C24 -> 75.85
B25: - плата за услуги по управлению изменением режима потребления электрической энергии | C25: 1.07 | D25: 1.07 | E25: 1.07 | F25: 1.07
B26: - инфраструктурные платежи | C26: =C20 -> 5.35 | D26: =C26 -> 5.35 | E26: =C26 -> 5.35 | F26: =C26 -> 5.35
A27: 1.1.1.3. | B27: пиковая зона | C27: =C28+C29+C30+C32+C31 -> 10653.27 | D27: =D28+D29+D30+D32+D31 -> 11443.2 | E27: =E28+E29+E30+E32+E31 -> 12095.21 | F27: =F28+F29+F30+F32+F31 -> 13771.37
B28: - средневзв. стоимость э/э (м) | C28: 9287.34 | D28: =C28 -> 9287.34 | E28: =C28 -> 9287.34 | F28: =C28 -> 9287.34
B29: - услуги по передаче | C29: =C17 -> 1283.66 | D29: =D17 -> 2073.59 | E29: =E17 -> 2725.6 | F29: =F17 -> 4401.76
B30: - сбытовая надбавка ГП | C30: 75.85 | D30: =C30 -> 75.85 | E30: =C30 -> 75.85 | F30: =C30 -> 75.85
B31: - плата за услуги по управлению изменением режима потребления электрической энергии | C31: 1.07 | D31: 1.07 | E31: 1.07 | F31: 1.07
B32: - инфраструктурные платежи | C32: =C20 -> 5.35 | D32: =C32 -> 5.35 | E32: =C32 -> 5.35 | F32: =C32 -> 5.35
A33: 1.1.2. | B33: Потребители, рассчитывающиеся по договорам купли-продажи
A34: 1.1.2.1. | B34: ночная зона | C34: =C35+C36+C38+C37 -> 1287.98 | D34: =D35+D36+D38+D37 -> 1287.98 | E34: =E35+E36+E38+E37 -> 1287.98 | F34: =F35+F36+F38+F37 -> 1287.98
B35: - средневзв. стоимость э/э (м) | C35: =C16 -> 1205.71 | D35: =C35 -> 1205.71 | E35: =C35 -> 1205.71 | F35: =C35 -> 1205.71
B36: - сбытовая надбавка ГП | C36: =C18 -> 75.85 | D36: =C36 -> 75.85 | E36: =C36 -> 75.85 | F36: =C36 -> 75.85
B37: - плата за услуги по управлению изменением режима потребления электрической энергии | C37: 1.07 | D37: 1.07 | E37: 1.07 | F37: 1.07
B38: - инфраструктурные платежи | C38: =C20 -> 5.35 | D38: =C38 -> 5.35 | E38: =C38 -> 5.35 | F38: =C38 -> 5.35
A39: 1.1.2.2. | B39: полупиковая зона | C39: =C40+C41+C43+C42 -> 4204.21 | D39: =D40+D41+D43+D42 -> 4204.21 | E39: =E40+E41+E43+E42 -> 4204.21 | F39: =F40+F41+F43+F42 -> 4204.21
B40: - средневзв. стоимость э/э (м) | C40: =C22 -> 4121.94 | D40: =C40 -> 4121.94 | E40: =C40 -> 4121.94 | F40: =C40 -> 4121.94
B41: - сбытовая надбавка ГП | C41: =C24 -> 75.85 | D41: =C41 -> 75.85 | E41: =C41 -> 75.85 | F41: =C41 -> 75.85
B42: - плата за услуги по управлению изменением режима потребления электрической энергии | C42: 1.07 | D42: 1.07 | E42: 1.07 | F42: 1.07
B43: - инфраструктурные платежи | C43: =C38 -> 5.35 | D43: =C43 -> 5.35 | E43: =C43 -> 5.35 | F43: =C43 -> 5.35
A44: 1.1.2.3. | B44: пиковая зона | C44: =C45+C46+C48+C47 -> 9369.61 | D44: =D45+D46+D48+D47 -> 9369.61 | E44: =E45+E46+E48+E47 -> 9369.61 | F44: =F45+F46+F48+F47 -> 9369.61
...

Sheet М_июль 3 цк
A2: ='М_июль 1 цк'!A2 -> Предельные уровни нерегулируемых цен на электрическую энергию (мощность), поставляемую АО "Мосэнергосбыт" потребителям
A3: ='М_июль 1 цк'!A3 -> с максимальной мощностью энергопринимающих устройств не менее 10 МВт
A4: ='М_июль 1 цк'!A4 -> г. Москва
A5: ='М_июль 1 цк'!A5 -> Июль 2025 г.
A7: III. Третья ценовая категория для объемов покупки электрической энергии (мощности), в отношении которых за расчетный период осуществляется почасовой учет, но не осуществляется почасовое планирование, а стоимость услуг по передаче электрической энергии определяется по тарифу на услуги по передаче электрической энергии в одноставочном выражении
A9: 1.1. Ставка за электрическую энергию предельного уровня нерегулируемых цен для абонентов группы "Иные прочие потребители", рублей/МВт∙ч без НДС
A11: Дата | B11: Ставка для фактических почасовых объемов покупки электрической энергии, отпущенных на уровне напряжения ВН
B12: 0:00-1:00 | C12: 1:00-2:00 | D12: 2:00-3:00 | E12: 3:00-4:00 | F12: 4:00-5:00 | G12: 5:00-6:00 | H12: 6:00-7:00 | I12: 7:00-8:00 | J12: 8:00-9:00 | K12: 9:00-10:00 | L12: 10:00-11:00 | M12: 11:00-12:00 | N12: 12:00-13:00 | O12: 13:00-14:00 | P12: 14:00-15:00 | Q12: 15:00-16:00 | R12: 16:00-17:00 | S12: 17:00-18:00 | T12: 18:00-19:00 | U12: 19:00-20:00 | V12: 20:00-21:00 | W12: 21:00-22:00 | X12: 22:00-23:00 | Y12: 23:00-0:00
A13: 1 | B13: =B14+B15+B16+B17 -> 3008.49 | C13: =C14+C15+C16+C17 -> 2739.95 | D13: =D14+D15+D16+D17 -> 2624.87 | E13: =E14+E15+E16+E17 -> 2524.07 | F13: =F14+F15+F16+F17 -> 2546.14 | G13: =G14+G15+G16+G17 -> 2831.43 | H13: =H14+H15+H16+H17 -> 2956.66 | I13: =I14+I15+I16+I17 -> 3408.52 | ... Y13: =Y14+Y15+Y16+Y17 -> 3430.63
A14: - средневзв. стоимость э/э (м) | B14: 1643.63 | C14: 1375.09 | D14: 1260.01 | E14: 1159.21 | F14: 1181.28 | G14: 1466.57 | H14: 1591.8 | I14: 2043.66 | J14: 2544.33 | K14: 2682.61 | L14: 2744.97 | M14: 2743.85 | N14: 2729.42 | O14: 2739.69 | P14: 2768.75 | Q14: 2783.49 | R14: 2762.56 | S14: 2768.68 | T14: 2746.78 | U14: 2697.44 | V14: 2663.63 | W14: 2636.06 | X14: 2326.79 | Y14: 2065.77
A15: - услуги по передаче | B15: 1283.66 | C15: =$B15 -> 1283.66 | D15: =$B15 -> 1283.66 | E15: =$B15 -> 1283.66 | F15: =$B15 -> 1283.66 | G15: =$B15 -> 1283.66 | H15: =$B15 -> 1283.66 | I15: =$B15 -> 1283.66 | J15: =$B15 -> 1283.66 | ... Y15: =$B15 -> 1283.66
A16: - сбытовая надбавка ГП | B16: 75.85 | C16: 75.85 | D16: 75.85 | E16: 75.85 | F16: 75.85 | G16: 75.85 | H16: 75.85 | I16: 75.85 | J16: 75.85 | K16: 75.85 | L16: 75.85 | M16: 75.85 | N16: 75.85 | O16: 75.85 | P16: 75.85 | Q16: 75.85 | R16: 75.85 | S16: 75.85 | T16: 75.85 | U16: 75.85 | V16: 75.85 | W16: 75.85 | X16: 75.85 | Y16: 75.85
A17: - инфраструктурные платежи | B17: 5.35 | C17: =$B17 -> 5.35 | D17: =$B17 -> 5.35 | E17: =$B17 -> 5.35 | F17: =$B17 -> 5.35 | G17: =$B17 -> 5.35 | H17: =$B17 -> 5.35 | I17: =$B17 -> 5.35 | J17: =$B17 -> 5.35 | ... Y17: =$B17 -> 5.35
A18: 2 | B18: =B19+B20+B21+B22 -> 3053.84 | C18: =C19+C20+C21+C22 -> 2893.86 | D18: =D19+D20+D21+D22 -> 2810.21 | E18: =E19+E20+E21+E22 -> 2594.71 | F18: =F19+F20+F21+F22 -> 2689.02 | G18: =G19+G20+G21+G22 -> 2890.07 | H18: =H19+H20+H21+H22 -> 2972.17 | I18: =I19+I20+I21+I22 -> 3459.2 | ... Y18: =Y19+Y20+Y21+Y22 -> 3365.24
A19: - средневзв. стоимость э/э (м) | B19: 1688.98 | C19: 1529 | D19: 1445.35 | E19: 1229.85 | F19: 1324.16 | G19: 1525.21 | H19: 1607.31 | I19: 2094.34 | J19: 2706.96 | K19: 2804.21 | L19: 2837.46 | M19: 2828.28 | N19: 2843.1 | O19: 2873.1 | P19: 2874.34 | Q19: 2863.78 | R19: 2837.34 | S19: 2817.79 | T19: 2806.9 | U19: 2778.96 | V19: 2748.46 | W19: 2727.03 | X19: 2445.18 | Y19: 2000.38
A20: - услуги по передаче | B20: =$B$15 -> 1283.66 | C20: =$B20 -> 1283.66 | D20: =$B20 -> 1283.66 | E20: =$B20 -> 1283.66 | F20: =$B20 -> 1283.66 | G20: =$B20 -> 1283.66 | H20: =$B20 -> 1283.66 | I20: =$B20 -> 1283.66 | J20: =$B20 -> 1283.66 | ... Y20: =$B20 -> 1283.66
A21: - сбытовая надбавка ГП | B21: 75.85 | C21: 75.85 | D21: 75.85 | E21: 75.85 | F21: 75.85 | G21: 75.85 | H21: 75.85 | I21: 75.85 | J21: 75.85 | K21: 75.85 | L21: 75.85 | M21: 75.85 | N21: 75.85 | O21: 75.85 | P21: 75.85 | Q21: 75.85 | R21: 75.85 | S21: 75.85 | T21: 75.85 | U21: 75.85 | V21: 75.85 | W21: 75.85 | X21: 75.85 | Y21: 75.85
A22: - инфраструктурные платежи | B22: =$B$17 -> 5.35 | C22: =$B22 -> 5.35 | D22: =$B22 -> 5.35 | E22: =$B22 -> 5.35 | F22: =$B22 -> 5.35 | G22: =$B22 -> 5.35 | H22: =$B22 -> 5.35 | I22: =$B22 -> 5.35 | J22: =$B22 -> 5.35 | ... Y22: =$B22 -> 5.35
A23: 3 | B23: =B24+B25+B26+B27 -> 2935.76 | C23: =C24+C25+C26+C27 -> 2777.57 | D23: =D24+D25+D26+D27 -> 2654.38 | E23: =E24+E25+E26+E27 -> 2538.68 | F23: =F24+F25+F26+F27 -> 2550.29 | G23: =G24+G25+G26+G27 -> 2775.75 | H23: =H24+H25+H26+H27 -> 2919.71 | I23: =I24+I25+I26+I27 -> 3373.9 | ... Y23: =Y24+Y25+Y26+Y27 -> 3353.52
A24: - средневзв. стоимость э/э (м) | B24: 1570.9 | C24: 1412.71 | D24: 1289.52 | E24: 1173.82 | F24: 1185.43 | G24: 1410.89 | H24: 1554.85 | I24: 2009.04 | J24: 2559.55 | K24: 2598.88 | L24: 2641.18 | M24: 2673.9 | N24: 2667.07 | O24: 2651.63 | P24: 2872.93 | Q24: 2941.52 | R24: 2884.71 | S24: 2688.33 | T24: 2757.86 | U24: 2651.34 | V24: 2696.89 | W24: 2677.99 | X24: 2417.66 | Y24: 1988.66
A25: - услуги по передаче | B25: =$B$15 -> 1283.66 | C25: =$B25 -> 1283.66 | D25: =$B25 -> 1283.66 | E25: =$B25 -> 1283.66 | F25: =$B25 -> 1283.66 | G25: =$B25 -> 1283.66 | H25: =$B25 -> 1283.66 | I25: =$B25 -> 1283.66 | J25: =$B25 -> 1283.66 | ... Y25: =$B25 -> 1283.66
A26: - сбытовая надбавка ГП | B26: 75.85 | C26: 75.85 | D26: 75.85 | E26: 75.85 | F26: 75.85 | G26: 75.85 | H26: 75.85 | I26: 75.85 | J26: 75.85 | K26: 75.85 | L26: 75.85 | M26: 75.85 | N26: 75.85 | O26: 75.85 | P26: 75.85 | Q26: 75.85 | R26: 75.85 | S26: 75.85 | T26: 75.85 | U26: 75.85 | V26: 75.85 | W26: 75.85 | X26: 75.85 | Y26: 75.85
A27: - инфраструктурные платежи | B27: =$B$17 -> 5.35 | C27: =$B27 -> 5.35 | D27: =$B27 -> 5.35 | E27: =$B27 -> 5.35 | F27: =$B27 -> 5.35 | G27: =$B27 -> 5.35 | H27: =$B27 -> 5.35 | I27: =$B27 -> 5.35 | J27: =$B27 -> 5.35 | ... Y27: =$B27 -> 5.35
A28: 4 | B28: =B29+B30+B31+B32 -> 3026.38 | C28: =C29+C30+C31+C32 -> 2806.35 | D28: =D29+D30+D31+D32 -> 2660.9 | E28: =E29+E30+E31+E32 -> 2531.62 | F28: =F29+F30+F31+F32 -> 2548.11 | G28: =G29+G30+G31+G32 -> 2780.66 | H28: =H29+H30+H31+H32 -> 2932.74 | I28: =I29+I30+I31+I32 -> 3395.36 | ... Y28: =Y29+Y30+Y31+Y32 -> 3410.36
A29: - средневзв. стоимость э/э (м) | B29: 1661.52 | C29: 1441.49 | D29: 1296.04 | E29: 1166.76 | F29: 1183.25 | G29: 1415.8 | H29: 1567.88 | I29: 2030.5 | J29: 2568.65 | K29: 2687.94 | L29: 2641.38 | M29: 2639.93 | N29: 2707.75 | O29: 2639.25 | P29: 2784.72 | Q29: 2836.9 | R29: 2818.07 | S29: 2794.9 | T29: 2781.67 | U29: 2648.88 | V29: 2631.45 | W29: 2708.37 | X29: 2511.35 | Y29: 2045.5
A30: - услуги по передаче | B30: =$B$15 -> 1283.66 | C30: =$B30 -> 1283.66 | D30: =$B30 -> 1283.66 | E30: =$B30 -> 1283.66 | F30: =$B30 -> 1283.66 | G30: =$B30 -> 1283.66 | H30: =$B30 -> 1283.66 | I30: =$B30 -> 1283.66 | J30: =$B30 -> 1283.66 | ... Y30: =$B30 -> 1283.66
A31: - сбытовая надбавка ГП | B31: 75.85 | C31: 75.85 | D31: 75.85 | E31: 75.85 | F31: 75.85 | G31: 75.85 | H31: 75.85 | I31: 75.85 | J31: 75.85 | K31: 75.85 | L31: 75.85 | M31: 75.85 | N31: 75.85 | O31: 75.85 | P31: 75.85 | Q31: 75.85 | R31: 75.85 | S31: 75.85 | T31: 75.85 | U31: 75.85 | V31: 75.85 | W31: 75.85 | X31: 75.85 | Y31: 75.85
A32: - инфраструктурные платежи | B32: =$B$17 -> 5.35 | C32: =$B32 -> 5.35 | D32: =$B32 -> 5.35 | E32: =$B32 -> 5.35 | F32: =$B32 -> 5.35 | G32: =$B32 -> 5.35 | H32: =$B32 -> 5.35 | I32: =$B32 -> 5.35 | J32: =$B32 -> 5.35 | ... Y32: =$B32 -> 5.35
A33: 5 | B33: =B34+B35+B36+B37 -> 3118.22 | C33: =C34+C35+C36+C37 -> 2883.99 | D33: =D34+D35+D36+D37 -> 2776.94 | E33: =E34+E35+E36+E37 -> 2633.8 | F33: =F34+F35+F36+F37 -> 2575.51 | G33: =G34+G35+G36+G37 -> 2566.56 | H33: =H34+H35+H36+H37 -> 2669.72 | I33: =I34+I35+I36+I37 -> 3033.88 | ... Y33: =Y34+Y35+Y36+Y37 -> 3346.02
A34: - средневзв. стоимость э/э (м) | B34: 1753.36 | C34: 1519.13 | D34: 1412.08 | E34: 1268.94 | F34: 1210.65 | G34: 1201.7 | H34: 1304.86 | I34: 1669.02 | J34: 2134.91 | K34: 2370.79 | L34: 2439.61 | M34: 2468.97 | N34: 2464.34 | O34: 2468.42 | P34: 2464.8 | Q34: 2527.1 | R34: 2535.38 | S34: 2500.69 | T34: 2480.64 | U34: 2452.58 | V34: 2450.49 | W34: 2467.58 | X34: 2169.48 | Y34: 1981.16
A35: - услуги по передаче | B35: =$B$15 -> 1283.66 | C35: =$B35 -> 1283.66 | D35: =$B35 -> 1283.66 | E35: =$B35 -> 1283.66 | F35: =$B35 -> 1283.66 | G35: =$B35 -> 1283.66 | H35: =$B35 -> 1283.66 | I35: =$B35 -> 1283.66 | J35: =$B35 -> 1283.66 | ... Y35: =$B35 -> 1283.66
A36: - сбытовая надбавка ГП | B36: 75.85 | C36: 75.85 | D36: 75.85 | E36: 75.85 | F36: 75.85 | G36: 75.85 | H36: 75.85 | I36: 75.85 | J36: 75.85 | K36: 75.85 | L36: 75.85 | M36: 75.85 | N36: 75.85 | O36: 75.85 | P36: 75.85 | Q36: 75.85 | R36: 75.85 | S36: 75.85 | T36: 75.85 | U36: 75.85 | V36: 75.85 | W36: 75.85 | X36: 75.85 | Y36: 75.85
A37: - инфраструктурные платежи | B37: =$B$17 -> 5.35 | C37: =$B37 -> 5.35 | D37: =$B37 -> 5.35 | E37: =$B37 -> 5.35 | F37: =$B37 -> 5.35 | G37: =$B37 -> 5.35 | H37: =$B37 -> 5.35 | I37: =$B37 -> 5.35 | J37: =$B37 -> 5.35 | ... Y37: =$B37 -> 5.35
A38: 6 | B38: =B39+B40+B41+B42 -> 3126.51 | C38: =C39+C40+C41+C42 -> 2872.44 | D38: =D39+D40+D41+D42 -> 2751.46 | E38: =E39+E40+E41+E42 -> 2565.83 | F38: =F39+F40+F41+F42 -> 2508.34 | G38: =G39+G40+G41+G42 -> 2507.27 | H38: =H39+H40+H41+H42 -> 2452.02 | I38: =I39+I40+I41+I42 -> 2880.87 | ... Y38: =Y39+Y40+Y41+Y42 -> 3207.4
A39: - средневзв. стоимость э/э (м) | B39: 1761.65 | C39: 1507.58 | D39: 1386.6 | E39: 1200.97 | F39: 1143.48 | G39: 1142.41 | H39: 1087.16 | I39: 1516.01 | J39: 1920.92 | K39: 2258.81 | L39: 2395.9 | M39: 2395.86 | N39: 2398.62 | O39: 2405.7 | P39: 2410.55 | Q39: 2412.36 | R39: 2465.57 | S39: 2451.43 | T39: 2449.76 | U39: 2433.67 | V39: 2433.2 | W39: 2429.4 | X39: 2185.02 | Y39: 1842.54
A40: - услуги по передаче | B40: =$B$15 -> 1283.66 | C40: =$B40 -> 1283.66 | D40: =$B40 -> 1283.66 | E40: =$B40 -> 1283.66 | F40: =$B40 -> 1283.66 | G40: =$B40 -> 1283.66 | H40: =$B40 -> 1283.66 | I40: =$B40 -> 1283.66 | J40: =$B40 -> 1283.66 | ... Y40: =$B40 -> 1283.66
A41: - сбытовая надбавка ГП | B41: 75.85 | C41: 75.85 | D41: 75.85 | E41: 75.85 | F41: 75.85 | G41: 75.85 | H41: 75.85 | I41: 75.85 | J41: 75.85 | K41: 75.85 | L41: 75.85 | M41: 75.85 | N41: 75.85 | O41: 75.85 | P41: 75.85 | Q41: 75.85 | R41: 75.85 | S41: 75.85 | T41: 75.85 | U41: 75.85 | V41: 75.85 | W41: 75.85 | X41: 75.85 | Y41: 75.85
A42: - инфраструктурные платежи | B42: =$B$17 -> 5.35 | C42: =$B42 -> 5.35 | D42: =$B42 -> 5.35 | E42: =$B42 -> 5.35 | F42: =$B42 -> 5.35 | G42: =$B42 -> 5.35 | H42: =$B42 -> 5.35 | I42: =$B42 -> 5.35 | J42: =$B42 -> 5.35 | ... Y42: =$B42 -> 5.35
A43: 7 | B43: =B44+B45+B46+B47 -> 3050.77 | C43: =C44+C45+C46+C47 -> 2882.24 | D43: =D44+D45+D46+D47 -> 2681.61 | E43: =E44+E45+E46+E47 -> 2536.88 | F43: =F44+F45+F46+F47 -> 2505.68 | G43: =G44+G45+G46+G47 -> 2595.26 | H43: =H44+H45+H46+H47 -> 2901.4 | I43: =I44+I45+I46+I47 -> 3342.63 | ... Y43: =Y44+Y45+Y46+Y47 -> 3234.94
A44: - средневзв. стоимость э/э (м) | B44: 1685.91 | C44: 1517.38 | D44: 1316.75 | E44: 1172.02 | F44: 1140.82 | G44: 1230.4 | H44: 1536.54 | I44: 1977.77 | J44: 2516.42 | K44: 2642.82 | L44: 2703.04 | M44: 2743.84 | N44: 2728.5 | O44: 2752.78 | P44: 2737.88 | Q44: 2771.21 | R44: 2719.3 | S44: 2834.06 | T44: 2733.83 | U44: 2697.7 | V44: 2643.26 | W44: 2659.85 | X44: 2219.27 | Y44: 1870.08
...

Sheet М_июль 4 цк
A2: ='М_июль 1 цк'!A2 -> Предельные уровни нерегулируемых цен на электрическую энергию (мощность), поставляемую АО "Мосэнергосбыт" потребителям
A3: ='М_июль 1 цк'!A3 -> с максимальной мощностью энергопринимающих устройств не менее 10 МВт
A4: ='М_июль 1 цк'!A4 -> г. Москва
A5: ='М_июль 1 цк'!A5 -> Июль 2025 г.
A7: IV. Четвертая ценовая категория для объемов покупки электрической энергии (мощности), в отношении которых за расчетный период осуществляется почасовой учет, но не осуществляется почасовое планирование, а стоимость услуг по передаче электрической энергии определяется по тарифу на услуги по передаче электрической энергии в двухставочном выражении
A9: 1.1. Ставка за электрическую энергию предельного уровня нерегулируемых цен для абонентов группы "Иные прочие потребители", рублей/МВт∙ч без НДС
A11: Дата | B11: Ставка для фактических почасовых объемов покупки электрической энергии, отпущенных на уровне напряжения ВН
B12: 0:00-1:00 | C12: 1:00-2:00 | D12: 2:00-3:00 | E12: 3:00-4:00 | F12: 4:00-5:00 | G12: 5:00-6:00 | H12: 6:00-7:00 | I12: 7:00-8:00 | J12: 8:00-9:00 | K12: 9:00-10:00 | L12: 10:00-11:00 | M12: 11:00-12:00 | N12: 12:00-13:00 | O12: 13:00-14:00 | P12: 14:00-15:00 | Q12: 15:00-16:00 | R12: 16:00-17:00 | S12: 17:00-18:00 | T12: 18:00-19:00 | U12: 19:00-20:00 | V12: 20:00-21:00 | W12: 21:00-22:00 | X12: 22:00-23:00 | Y12: 23:00-0:00
A13: 1 | B13: =B14+B15+B16+B17 -> 1805.41 | C13: =C14+C15+C16+C17 -> 1536.87 | D13: =D14+D15+D16+D17 -> 1421.79 | E13: =E14+E15+E16+E17 -> 1320.99 | F13: =F14+F15+F16+F17 -> 1343.06 | G13: =G14+G15+G16+G17 -> 1628.35 | H13: =H14+H15+H16+H17 -> 1753.58 | I13: =I14+I15+I16+I17 -> 2205.44 | ... Y13: =Y14+Y15+Y16+Y17 -> 2227.55
A14: - средневзв. стоимость э/э (м) | B14: 1643.63 | C14: 1375.09 | D14: 1260.01 | E14: 1159.21 | F14: 1181.28 | G14: 1466.57 | H14: 1591.8 | I14: 2043.66 | J14: 2544.33 | K14: 2682.61 | L14: 2744.97 | M14: 2743.85 | N14: 2729.42 | O14: 2739.69 | P14: 2768.75 | Q14: 2783.49 | R14: 2762.56 | S14: 2768.68 | T14: 2746.78 | U14: 2697.44 | V14: 2663.63 | W14: 2636.06 | X14: 2326.79 | Y14: 2065.77
A15: - услуги по передаче | B15: 80.58 | C15: =$B15 -> 80.58 | D15: =$B15 -> 80.58 | E15: =$B15 -> 80.58 | F15: =$B15 -> 80.58 | G15: =$B15 -> 80.58 | H15: =$B15 -> 80.58 | I15: =$B15 -> 80.58 | J15: =$B15 -> 80.58 | ... Y15: =$B15 -> 80.58
A16: - сбытовая надбавка ГП | B16: 75.85 | C16: 75.85 | D16: 75.85 | E16: 75.85 | F16: 75.85 | G16: 75.85 | H16: 75.85 | I16: 75.85 | J16: 75.85 | K16: 75.85 | L16: 75.85 | M16: 75.85 | N16: 75.85 | O16: 75.85 | P16: 75.85 | Q16: 75.85 | R16: 75.85 | S16: 75.85 | T16: 75.85 | U16: 75.85 | V16: 75.85 | W16: 75.85 | X16: 75.85 | Y16: 75.85
A17: - инфраструктурные платежи | B17: 5.35 | C17: =$B17 -> 5.35 | D17: =$B17 -> 5.35 | E17: =$B17 -> 5.35 | F17: =$B17 -> 5.35 | G17: =$B17 -> 5.35 | H17: =$B17 -> 5.35 | I17: =$B17 -> 5.35 | J17: =$B17 -> 5.35 | ... Y17: =$B17 -> 5.35
A18: 2 | B18: =B19+B20+B21+B22 -> 1850.76 | C18: =C19+C20+C21+C22 -> 1690.78 | D18: =D19+D20+D21+D22 -> 1607.13 | E18: =E19+E20+E21+E22 -> 1391.63 | F18: =F19+F20+F21+F22 -> 1485.94 | G18: =G19+G20+G21+G22 -> 1686.99 | H18: =H19+H20+H21+H22 -> 1769.09 | I18: =I19+I20+I21+I22 -> 2256.12 | ... Y18: =Y19+Y20+Y21+Y22 -> 2162.16
A19: - средневзв. стоимость э/э (м) | B19: 1688.98 | C19: 1529 | D19: 1445.35 | E19: 1229.85 | F19: 1324.16 | G19: 1525.21 | H19: 1607.31 | I19: 2094.34 | J19: 2706.96 | K19: 2804.21 | L19: 2837.46 | M19: 2828.28 | N19: 2843.1 | O19: 2873.1 | P19: 2874.34 | Q19: 2863.78 | R19: 2837.34 | S19: 2817.79 | T19: 2806.9 | U19: 2778.96 | V19: 2748.46 | W19: 2727.03 | X19: 2445.18 | Y19: 2000.38
A20: - услуги по передаче | B20: =$B$15 -> 80.58 | C20: =$B20 -> 80.58 | D20: =$B20 -> 80.58 | E20: =$B20 -> 80.58 | F20: =$B20 -> 80.58 | G20: =$B20 -> 80.58 | H20: =$B20 -> 80.58 | I20: =$B20 -> 80.58 | J20: =$B20 -> 80.58 | ... Y20: =$B20 -> 80.58
A21: - сбытовая надбавка ГП | B21: 75.85 | C21: 75.85 | D21: 75.85 | E21: 75.85 | F21: 75.85 | G21: 75.85 | H21: 75.85 | I21: 75.85 | J21: 75.85 | K21: 75.85 | L21: 75.85 | M21: 75.85 | N21: 75.85 | O21: 75.85 | P21: 75.85 | Q21: 75.85 | R21: 75.85 | S21: 75.85 | T21: 75.85 | U21: 75.85 | V21: 75.85 | W21: 75.85 | X21: 75.85 | Y21: 75.85
A22: - инфраструктурные платежи | B22: =$B$17 -> 5.35 | C22: =$B22 -> 5.35 | D22: =$B22 -> 5.35 | E22: =$B22 -> 5.35 | F22: =$B22 -> 5.35 | G22: =$B22 -> 5.35 | H22: =$B22 -> 5.35 | I22: =$B22 -> 5.35 | J22: =$B22 -> 5.35 | ... Y22: =$B22 -> 5.35
A23: 3 | B23: =B24+B25+B26+B27 -> 1732.68 | C23: =C24+C25+C26+C27 -> 1574.49 | D23: =D24+D25+D26+D27 -> 1451.3 | E23: =E24+E25+E26+E27 -> 1335.6 | F23: =F24+F25+F26+F27 -> 1347.21 | G23: =G24+G25+G26+G27 -> 1572.67 | H23: =H24+H25+H26+H27 -> 1716.63 | I23: =I24+I25+I26+I27 -> 2170.82 | ... Y23: =Y24+Y25+Y26+Y27 -> 2150.44
A24: - средневзв. стоимость э/э (м) | B24: 1570.9 | C24: 1412.71 | D24: 1289.52 | E24: 1173.82 | F24: 1185.43 | G24: 1410.89 | H24: 1554.85 | I24: 2009.04 | J24: 2559.55 | K24: 2598.88 | L24: 2641.18 | M24: 2673.9 | N24: 2667.07 | O24: 2651.63 | P24: 2872.93 | Q24: 2941.52 | R24: 2884.71 | S24: 2688.33 | T24: 2757.86 | U24: 2651.34 | V24: 2696.89 | W24: 2677.99 | X24: 2417.66 | Y24: 1988.66
A25: - услуги по передаче | B25: =$B$15 -> 80.58 | C25: =$B25 -> 80.58 | D25: =$B25 -> 80.58 | E25: =$B25 -> 80.58 | F25: =$B25 -> 80.58 | G25: =$B25 -> 80.58 | H25: =$B25 -> 80.58 | I25: =$B25 -> 80.58 | J25: =$B25 -> 80.58 | ... Y25: =$B25 -> 80.58
A26: - сбытовая надбавка ГП | B26: 75.85 | C26: 75.85 | D26: 75.85 | E26: 75.85 | F26: 75.85 | G26: 75.85 | H26: 75.85 | I26: 75.85 | J26: 75.85 | K26: 75.85 | L26: 75.85 | M26: 75.85 | N26: 75.85 | O26: 75.85 | P26: 75.85 | Q26: 75.85 | R26: 75.85 | S26: 75.85 | T26: 75.85 | U26: 75.85 | V26: 75.85 | W26: 75.85 | X26: 75.85 | Y26: 75.85
A27: - инфраструктурные платежи | B27: =$B$17 -> 5.35 | C27: =$B27 -> 5.35 | D27: =$B27 -> 5.35 | E27: =$B27 -> 5.35 | F27: =$B27 -> 5.35 | G27: =$B27 -> 5.35 | H27: =$B27 -> 5.35 | I27: =$B27 -> 5.35 | J27: =$B27 -> 5.35 | ... Y27: =$B27 -> 5.35
A28: 4 | B28: =B29+B30+B31+B32 -> 1823.3 | C28: =C29+C30+C31+C32 -> 1603.27 | D28: =D29+D30+D31+D32 -> 1457.82 | E28: =E29+E30+E31+E32 -> 1328.54 | F28: =F29+F30+F31+F32 -> 1345.03 | G28: =G29+G30+G31+G32 -> 1577.58 | H28: =H29+H30+H31+H32 -> 1729.66 | I28: =I29+I30+I31+I32 -> 2192.28 | ... Y28: =Y29+Y30+Y31+Y32 -> 2207.28
A29: - средневзв. стоимость э/э (м) | B29: 1661.52 | C29: 1441.49 | D29: 1296.04 | E29: 1166.76 | F29: 1183.25 | G29: 1415.8 | H29: 1567.88 | I29: 2030.5 | J29: 2568.65 | K29: 2687.94 | L29: 2641.38 | M29: 2639.93 | N29: 2707.75 | O29: 2639.25 | P29: 2784.72 | Q29: 2836.9 | R29: 2818.07 | S29: 2794.9 | T29: 2781.67 | U29: 2648.88 | V29: 2631.45 | W29: 2708.37 | X29: 2511.35 | Y29: 2045.5
A30: - услуги по передаче | B30: =$B$15 -> 80.58 | C30: =$B30 -> 80.58 | D30: =$B30 -> 80.58 | E30: =$B30 -> 80.58 | F30: =$B30 -> 80.58 | G30: =$B30 -> 80.58 | H30: =$B30 -> 80.58 | I30: =$B30 -> 80.58 | J30: =$B30 -> 80.58 | ... Y30: =$B30 -> 80.58
A31: - сбытовая надбавка ГП | B31: 75.85 | C31: 75.85 | D31: 75.85 | E31: 75.85 | F31: 75.85 | G31: 75.85 | H31: 75.85 | I31: 75.85 | J31: 75.85 | K31: 75.85 | L31: 75.85 | M31: 75.85 | N31: 75.85 | O31: 75.85 | P31: 75.85 | Q31: 75.85 | R31: 75.85 | S31: 75.85 | T31: 75.85 | U31: 75.85 | V31: 75.85 | W31: 75.85 | X31: 75.85 | Y31: 75.85
A32: - инфраструктурные платежи | B32: =$B$17 -> 5.35 | C32: =$B32 -> 5.35 | D32: =$B32 -> 5.35 | E32: =$B32 -> 5.35 | F32: =$B32 -> 5.35 | G32: =$B32 -> 5.35 | H32: =$B32 -> 5.35 | I32: =$B32 -> 5.35 | J32: =$B32 -> 5.35 | ... Y32: =$B32 -> 5.35
A33: 5 | B33: =B34+B35+B36+B37 -> 1915.14 | C33: =C34+C35+C36+C37 -> 1680.91 | D33: =D34+D35+D36+D37 -> 1573.86 | E33: =E34+E35+E36+E37 -> 1430.72 | F33: =F34+F35+F36+F37 -> 1372.43 | G33: =G34+G35+G36+G37 -> 1363.48 | H33: =H34+H35+H36+H37 -> 1466.64 | I33: =I34+I35+I36+I37 -> 1830.8 | ... Y33: =Y34+Y35+Y36+Y37 -> 2142.94
A34: - средневзв. стоимость э/э (м) | B34: 1753.36 | C34: 1519.13 | D34: 1412.08 | E34: 1268.94 | F34: 1210.65 | G34: 1201.7 | H34: 1304.86 | I34: 1669.02 | J34: 2134.91 | K34: 2370.79 | L34: 2439.61 | M34: 2468.97 | N34: 2464.34 | O34: 2468.42 | P34: 2464.8 | Q34: 2527.1 | R34: 2535.38 | S34: 2500.69 | T34: 2480.64 | U34: 2452.58 | V34: 2450.49 | W34: 2467.58 | X34: 2169.48 | Y34: 1981.16
A35: - услуги по передаче | B35: =$B$15 -> 80.58 | C35: =$B35 -> 80.58 | D35: =$B35 -> 80.58 | E35: =$B35 -> 80.58 | F35: =$B35 -> 80.58 | G35: =$B35 -> 80.58 | H35: =$B35 -> 80.58 | I35: =$B35 -> 80.58 | J35: =$B35 -> 80.58 | ... Y35: =$B35 -> 80.58
A36: - сбытовая надбавка ГП | B36: 75.85 | C36: 75.85 | D36: 75.85 | E36: 75.85 | F36: 75.85 | G36: 75.85 | H36: 75.85 | I36: 75.85 | J36: 75.85 | K36: 75.85 | L36: 75.85 | M36: 75.85 | N36: 75.85 | O36: 75.85 | P36: 75.85 | Q36: 75.85 | R36: 75.85 | S36: 75.85 | T36: 75.85 | U36: 75.85 | V36: 75.85 | W36: 75.85 | X36: 75.85 | Y36: 75.85
A37: - инфраструктурные платежи | B37: =$B$17 -> 5.35 | C37: =$B37 -> 5.35 | D37: =$B37 -> 5.35 | E37: =$B37 -> 5.35 | F37: =$B37 -> 5.35 | G37: =$B37 -> 5.35 | H37: =$B37 -> 5.35 | I37: =$B37 -> 5.35 | J37: =$B37 -> 5.35 | ... Y37: =$B37 -> 5.35
A38: 6 | B38: =B39+B40+B41+B42 -> 1923.43 | C38: =C39+C40+C41+C42 -> 1669.36 | D38: =D39+D40+D41+D42 -> 1548.38 | E38: =E39+E40+E41+E42 -> 1362.75 | F38: =F39+F40+F41+F42 -> 1305.26 | G38: =G39+G40+G41+G42 -> 1304.19 | H38: =H39+H40+H41+H42 -> 1248.94 | I38: =I39+I40+I41+I42 -> 1677.79 | ... Y38: =Y39+Y40+Y41+Y42 -> 2004.32
A39: - средневзв. стоимость э/э (м) | B39: 1761.65 | C39: 1507.58 | D39: 1386.6 | E39: 1200.97 | F39: 1143.48 | G39: 1142.41 | H39: 1087.16 | I39: 1516.01 | J39: 1920.92 | K39: 2258.81 | L39: 2395.9 | M39: 2395.86 | N39: 2398.62 | O39: 2405.7 | P39: 2410.55 | Q39: 2412.36 | R39: 2465.57 | S39: 2451.43 | T39: 2449.76 | U39: 2433.67 | V39: 2433.2 | W39: 2429.4 | X39: 2185.02 | Y39: 1842.54
A40: - услуги по передаче | B40: =$B$15 -> 80.58 | C40: =$B40 -> 80.58 | D40: =$B40 -> 80.58 | E40: =$B40 -> 80.58 | F40: =$B40 -> 80.58 | G40: =$B40 -> 80.58 | H40: =$B40 -> 80.58 | I40: =$B40 -> 80.58 | J40: =$B40 -> 80.58 | ... Y40: =$B40 -> 80.58
A41: - сбытовая надбавка ГП | B41: 75.85 | C41: 75.85 | D41: 75.85 | E41: 75.85 | F41: 75.85 | G41: 75.85 | H41: 75.85 | I41: 75.85 | J41: 75.85 | K41: 75.85 | L41: 75.85 | M41: 75.85 | N41: 75.85 | O41: 75.85 | P41: 75.85 | Q41: 75.85 | R41: 75.85 | S41: 75.85 | T41: 75.85 | U41: 75.85 | V41: 75.85 | W41: 75.85 | X41: 75.85 | Y41: 75.85
A42: - инфраструктурные платежи | B42: =$B$17 -> 5.35 | C42: =$B42 -> 5.35 | D42: =$B42 -> 5.35 | E42: =$B42 -> 5.35 | F42: =$B42 -> 5.35 | G42: =$B42 -> 5.35 | H42: =$B42 -> 5.35 | I42: =$B42 -> 5.35 | J42: =$B42 -> 5.35 | ... Y42: =$B42 -> 5.35
A43: 7 | B43: =B44+B45+B46+B47 -> 1847.69 | C43: =C44+C45+C46+C47 -> 1679.16 | D43: =D44+D45+D46+D47 -> 1478.53 | E43: =E44+E45+E46+E47 -> 1333.8 | F43: =F44+F45+F46+F47 -> 1302.6 | G43: =G44+G45+G46+G47 -> 1392.18 | H43: =H44+H45+H46+H47 -> 1698.32 | I43: =I44+I45+I46+I47 -> 2139.55 | ... Y43: =Y44+Y45+Y46+Y47 -> 2031.86
A44: - средневзв. стоимость э/э (м) | B44: 1685.91 | C44: 1517.38 | D44: 1316.75 | E44: 1172.02 | F44: 1140.82 | G44: 1230.4 | H44: 1536.54 | I44: 1977.77 | J44: 2516.42 | K44: 2642.82 | L44: 2703.04 | M44: 2743.84 | N44: 2728.5 | O44: 2752.78 | P44: 2737.88 | Q44: 2771.21 | R44: 2719.3 | S44: 2834.06 | T44: 2733.83 | U44: 2697.7 | V44: 2643.26 | W44: 2659.85 | X44: 2219.27 | Y44: 1870.08
...

Sheet М_июль 5 цк
A2: ='М_июль 1 цк'!A2 -> Предельные уровни нерегулируемых цен на электрическую энергию (мощность), поставляемую АО "Мосэнергосбыт" потребителям
A3: ='М_июль 1 цк'!A3 -> с максимальной мощностью энергопринимающих устройств не менее 10 МВт
A4: ='М_июль 1 цк'!A4 -> г. Москва
A5: ='М_июль 1 цк'!A5 -> Июль 2025 г.
A7: V. Пятая ценовая категория для объемов покупки электрической энергии (мощности), в отношении которых за расчетный период осуществляются почасовое планирование и учет, а стоимость услуг по передаче электрической энергии определяется по тарифу на услуги по передаче электрической энергии в одноставочном выражении
A9: 1.1. Ставка за электрическую энергию предельного уровня нерегулируемых цен для абонентов группы "Иные прочие потребители", рублей/МВт∙ч без НДС
A11: Дата | B11: Ставка для фактических почасовых объемов покупки электрической энергии, отпущенных на уровне напряжения ВН
B12: 0:00-1:00 | C12: 1:00-2:00 | D12: 2:00-3:00 | E12: 3:00-4:00 | F12: 4:00-5:00 | G12: 5:00-6:00 | H12: 6:00-7:00 | I12: 7:00-8:00 | J12: 8:00-9:00 | K12: 9:00-10:00 | L12: 10:00-11:00 | M12: 11:00-12:00 | N12: 12:00-13:00 | O12: 13:00-14:00 | P12: 14:00-15:00 | Q12: 15:00-16:00 | R12: 16:00-17:00 | S12: 17:00-18:00 | T12: 18:00-19:00 | U12: 19:00-20:00 | V12: 20:00-21:00 | W12: 21:00-22:00 | X12: 22:00-23:00 | Y12: 23:00-0:00
A13: 1 | B13: =B14+B15+B16+B17 -> 2993.72 | C13: =C14+C15+C16+C17 -> 2725.18 | D13: =D14+D15+D16+D17 -> 2610.1 | E13: =E14+E15+E16+E17 -> 2509.3 | F13: =F14+F15+F16+F17 -> 2531.37 | G13: =G14+G15+G16+G17 -> 2816.66 | H13: =H14+H15+H16+H17 -> 2941.89 | I13: =I14+I15+I16+I17 -> 3393.75 | ... Y13: =Y14+Y15+Y16+Y17 -> 3415.86
A14: - средневзв. стоимость э/э (м) | B14: 1628.86 | C14: 1360.32 | D14: 1245.24 | E14: 1144.44 | F14: 1166.51 | G14: 1451.8 | H14: 1577.03 | I14: 2028.89 | J14: 2529.56 | K14: 2667.84 | L14: 2730.2 | M14: 2729.08 | N14: 2714.65 | O14: 2724.92 | P14: 2753.98 | Q14: 2768.72 | R14: 2747.79 | S14: 2753.91 | T14: 2732.01 | U14: 2682.67 | V14: 2648.86 | W14: 2621.29 | X14: 2312.02 | Y14: 2051
A15: - услуги по передаче | B15: 1283.66 | C15: =$B15 -> 1283.66 | D15: =$B15 -> 1283.66 | E15: =$B15 -> 1283.66 | F15: =$B15 -> 1283.66 | G15: =$B15 -> 1283.66 | H15: =$B15 -> 1283.66 | I15: =$B15 -> 1283.66 | J15: =$B15 -> 1283.66 | ... Y15: =$B15 -> 1283.66
A16: - сбытовая надбавка ГП | B16: 75.85 | C16: 75.85 | D16: 75.85 | E16: 75.85 | F16: 75.85 | G16: 75.85 | H16: 75.85 | I16: 75.85 | J16: 75.85 | K16: 75.85 | L16: 75.85 | M16: 75.85 | N16: 75.85 | O16: 75.85 | P16: 75.85 | Q16: 75.85 | R16: 75.85 | S16: 75.85 | T16: 75.85 | U16: 75.85 | V16: 75.85 | W16: 75.85 | X16: 75.85 | Y16: 75.85
A17: - инфраструктурные платежи | B17: 5.35 | C17: =$B17 -> 5.35 | D17: =$B17 -> 5.35 | E17: =$B17 -> 5.35 | F17: =$B17 -> 5.35 | G17: =$B17 -> 5.35 | H17: =$B17 -> 5.35 | I17: =$B17 -> 5.35 | J17: =$B17 -> 5.35 | ... Y17: =$B17 -> 5.35
A18: 2 | B18: =B19+B20+B21+B22 -> 3039.07 | C18: =C19+C20+C21+C22 -> 2879.09 | D18: =D19+D20+D21+D22 -> 2795.44 | E18: =E19+E20+E21+E22 -> 2579.94 | F18: =F19+F20+F21+F22 -> 2674.25 | G18: =G19+G20+G21+G22 -> 2875.3 | H18: =H19+H20+H21+H22 -> 2957.4 | I18: =I19+I20+I21+I22 -> 3444.43 | ... Y18: =Y19+Y20+Y21+Y22 -> 3350.47
A19: - средневзв. стоимость э/э (м) | B19: 1674.21 | C19: 1514.23 | D19: 1430.58 | E19: 1215.08 | F19: 1309.39 | G19: 1510.44 | H19: 1592.54 | I19: 2079.57 | J19: 2692.19 | K19: 2789.44 | L19: 2822.69 | M19: 2813.51 | N19: 2828.33 | O19: 2858.33 | P19: 2859.57 | Q19: 2849.01 | R19: 2822.57 | S19: 2803.02 | T19: 2792.13 | U19: 2764.19 | V19: 2733.69 | W19: 2712.26 | X19: 2430.41 | Y19: 1985.61
A20: - услуги по передаче | B20: =$B$15 -> 1283.66 | C20: =$B20 -> 1283.66 | D20: =$B20 -> 1283.66 | E20: =$B20 -> 1283.66 | F20: =$B20 -> 1283.66 | G20: =$B20 -> 1283.66 | H20: =$B20 -> 1283.66 | I20: =$B20 -> 1283.66 | J20: =$B20 -> 1283.66 | ... Y20: =$B20 -> 1283.66
A21: - сбытовая надбавка ГП | B21: 75.85 | C21: 75.85 | D21: 75.85 | E21: 75.85 | F21: 75.85 | G21: 75.85 | H21: 75.85 | I21: 75.85 | J21: 75.85 | K21: 75.85 | L21: 75.85 | M21: 75.85 | N21: 75.85 | O21: 75.85 | P21: 75.85 | Q21: 75.85 | R21: 75.85 | S21: 75.85 | T21: 75.85 | U21: 75.85 | V21: 75.85 | W21: 75.85 | X21: 75.85 | Y21: 75.85
A22: - инфраструктурные платежи | B22: =$B$17 -> 5.35 | C22: =$B22 -> 5.35 | D22: =$B22 -> 5.35 | E22: =$B22 -> 5.35 | F22: =$B22 -> 5.35 | G22: =$B22 -> 5.35 | H22: =$B22 -> 5.35 | I22: =$B22 -> 5.35 | J22: =$B22 -> 5.35 | ... Y22: =$B22 -> 5.35
A23: 3 | B23: =B24+B25+B26+B27 -> 2920.99 | C23: =C24+C25+C26+C27 -> 2762.8 | D23: =D24+D25+D26+D27 -> 2639.61 | E23: =E24+E25+E26+E27 -> 2523.91 | F23: =F24+F25+F26+F27 -> 2535.52 | G23: =G24+G25+G26+G27 -> 2760.98 | H23: =H24+H25+H26+H27 -> 2904.94 | I23: =I24+I25+I26+I27 -> 3359.13 | ... Y23: =Y24+Y25+Y26+Y27 -> 3338.75
A24: - средневзв. стоимость э/э (м) | B24: 1556.13 | C24: 1397.94 | D24: 1274.75 | E24: 1159.05 | F24: 1170.66 | G24: 1396.12 | H24: 1540.08 | I24: 1994.27 | J24: 2544.78 | K24: 2584.11 | L24: 2626.41 | M24: 2659.13 | N24: 2652.3 | O24: 2636.86 | P24: 2858.16 | Q24: 2926.75 | R24: 2869.94 | S24: 2673.56 | T24: 2743.09 | U24: 2636.57 | V24: 2682.12 | W24: 2663.22 | X24: 2402.89 | Y24: 1973.89
A25: - услуги по передаче | B25: =$B$15 -> 1283.66 | C25: =$B25 -> 1283.66 | D25: =$B25 -> 1283.66 | E25: =$B25 -> 1283.66 | F25: =$B25 -> 1283.66 | G25: =$B25 -> 1283.66 | H25: =$B25 -> 1283.66 | I25: =$B25 -> 1283.66 | J25: =$B25 -> 1283.66 | ... Y25: =$B25 -> 1283.66
A26: - сбытовая надбавка ГП | B26: 75.85 | C26: 75.85 | D26: 75.85 | E26: 75.85 | F26: 75.85 | G26: 75.85 | H26: 75.85 | I26: 75.85 | J26: 75.85 | K26: 75.85 | L26: 75.85 | M26: 75.85 | N26: 75.85 | O26: 75.85 | P26: 75.85 | Q26: 75.85 | R26: 75.85 | S26: 75.85 | T26: 75.85 | U26: 75.85 | V26: 75.85 | W26: 75.85 | X26: 75.85 | Y26: 75.85
A27: - инфраструктурные платежи | B27: =$B$17 -> 5.35 | C27: =$B27 -> 5.35 | D27: =$B27 -> 5.35 | E27: =$B27 -> 5.35 | F27: =$B27 -> 5.35 | G27: =$B27 -> 5.35 | H27: =$B27 -> 5.35 | I27: =$B27 -> 5.35 | J27: =$B27 -> 5.35 | ... Y27: =$B27 -> 5.35
A28: 4 | B28: =B29+B30+B31+B32 -> 3011.61 | C28: =C29+C30+C31+C32 -> 2791.58 | D28: =D29+D30+D31+D32 -> 2646.13 | E28: =E29+E30+E31+E32 -> 2516.85 | F28: =F29+F30+F31+F32 -> 2533.34 | G28: =G29+G30+G31+G32 -> 2765.89 | H28: =H29+H30+H31+H32 -> 2917.97 | I28: =I29+I30+I31+I32 -> 3380.59 | ... Y28: =Y29+Y30+Y31+Y32 -> 3395.59
A29: - средневзв. стоимость э/э (м) | B29: 1646.75 | C29: 1426.72 | D29: 1281.27 | E29: 1151.99 | F29: 1168.48 | G29: 1401.03 | H29: 1553.11 | I29: 2015.73 | J29: 2553.88 | K29: 2673.17 | L29: 2626.61 | M29: 2625.16 | N29: 2692.98 | O29: 2624.48 | P29: 2769.95 | Q29: 2822.13 | R29: 2803.3 | S29: 2780.13 | T29: 2766.9 | U29: 2634.11 | V29: 2616.68 | W29: 2693.6 | X29: 2496.58 | Y29: 2030.73
A30: - услуги по передаче | B30: =$B$15 -> 1283.66 | C30: =$B30 -> 1283.66 | D30: =$B30 -> 1283.66 | E30: =$B30 -> 1283.66 | F30: =$B30 -> 1283.66 | G30: =$B30 -> 1283.66 | H30: =$B30 -> 1283.66 | I30: =$B30 -> 1283.66 | J30: =$B30 -> 1283.66 | ... Y30: =$B30 -> 1283.66
A31: - сбытовая надбавка ГП | B31: 75.85 | C31: 75.85 | D31: 75.85 | E31: 75.85 | F31: 75.85 | G31: 75.85 | H31: 75.85 | I31: 75.85 | J31: 75.85 | K31: 75.85 | L31: 75.85 | M31: 75.85 | N31: 75.85 | O31: 75.85 | P31: 75.85 | Q31: 75.85 | R31: 75.85 | S31: 75.85 | T31: 75.85 | U31: 75.85 | V31: 75.85 | W31: 75.85 | X31: 75.85 | Y31: 75.85
A32: - инфраструктурные платежи | B32: =$B$17 -> 5.35 | C32: =$B32 -> 5.35 | D32: =$B32 -> 5.35 | E32: =$B32 -> 5.35 | F32: =$B32 -> 5.35 | G32: =$B32 -> 5.35 | H32: =$B32 -> 5.35 | I32: =$B32 -> 5.35 | J32: =$B32 -> 5.35 | ... Y32: =$B32 -> 5.35
A33: 5 | B33: =B34+B35+B36+B37 -> 3103.45 | C33: =C34+C35+C36+C37 -> 2869.22 | D33: =D34+D35+D36+D37 -> 2762.17 | E33: =E34+E35+E36+E37 -> 2619.03 | F33: =F34+F35+F36+F37 -> 2560.74 | G33: =G34+G35+G36+G37 -> 2551.79 | H33: =H34+H35+H36+H37 -> 2654.95 | I33: =I34+I35+I36+I37 -> 3019.11 | ... Y33: =Y34+Y35+Y36+Y37 -> 3331.25
A34: - средневзв. стоимость э/э (м) | B34: 1738.59 | C34: 1504.36 | D34: 1397.31 | E34: 1254.17 | F34: 1195.88 | G34: 1186.93 | H34: 1290.09 | I34: 1654.25 | J34: 2120.14 | K34: 2356.02 | L34: 2424.84 | M34: 2454.2 | N34: 2449.57 | O34: 2453.65 | P34: 2450.03 | Q34: 2512.33 | R34: 2520.61 | S34: 2485.92 | T34: 2465.87 | U34: 2437.81 | V34: 2435.72 | W34: 2452.81 | X34: 2154.71 | Y34: 1966.39
A35: - услуги по передаче | B35: =$B$15 -> 1283.66 | C35: =$B35 -> 1283.66 | D35: =$B35 -> 1283.66 | E35: =$B35 -> 1283.66 | F35: =$B35 -> 1283.66 | G35: =$B35 -> 1283.66 | H35: =$B35 -> 1283.66 | I35: =$B35 -> 1283.66 | J35: =$B35 -> 1283.66 | ... Y35: =$B35 -> 1283.66
A36: - сбытовая надбавка ГП | B36: 75.85 | C36: 75.85 | D36: 75.85 | E36: 75.85 | F36: 75.85 | G36: 75.85 | H36: 75.85 | I36: 75.85 | J36: 75.85 | K36: 75.85 | L36: 75.85 | M36: 75.85 | N36: 75.85 | O36: 75.85 | P36: 75.85 | Q36: 75.85 | R36: 75.85 | S36: 75.85 | T36: 75.85 | U36: 75.85 | V36: 75.85 | W36: 75.85 | X36: 75.85 | Y36: 75.85
A37: - инфраструктурные платежи | B37: =$B$17 -> 5.35 | C37: =$B37 -> 5.35 | D37: =$B37 -> 5.35 | E37: =$B37 -> 5.35 | F37: =$B37 -> 5.35 | G37: =$B37 -> 5.35 | H37: =$B37 -> 5.35 | I37: =$B37 -> 5.35 | J37: =$B37 -> 5.35 | ... Y37: =$B37 -> 5.35
A38: 6 | B38: =B39+B40+B41+B42 -> 3111.74 | C38: =C39+C40+C41+C42 -> 2857.67 | D38: =D39+D40+D41+D42 -> 2736.69 | E38: =E39+E40+E41+E42 -> 2551.06 | F38: =F39+F40+F41+F42 -> 2493.57 | G38: =G39+G40+G41+G42 -> 2492.5 | H38: =H39+H40+H41+H42 -> 2437.25 | I38: =I39+I40+I41+I42 -> 2866.1 | ... Y38: =Y39+Y40+Y41+Y42 -> 3192.63
A39: - средневзв. стоимость э/э (м) | B39: 1746.88 | C39: 1492.81 | D39: 1371.83 | E39: 1186.2 | F39: 1128.71 | G39: 1127.64 | H39: 1072.39 | I39: 1501.24 | J39: 1906.15 | K39: 2244.04 | L39: 2381.13 | M39: 2381.09 | N39: 2383.85 | O39: 2390.93 | P39: 2395.78 | Q39: 2397.59 | R39: 2450.8 | S39: 2436.66 | T39: 2434.99 | U39: 2418.9 | V39: 2418.43 | W39: 2414.63 | X39: 2170.25 | Y39: 1827.77
A40: - услуги по передаче | B40: =$B$15 -> 1283.66 | C40: =$B40 -> 1283.66 | D40: =$B40 -> 1283.66 | E40: =$B40 -> 1283.66 | F40: =$B40 -> 1283.66 | G40: =$B40 -> 1283.66 | H40: =$B40 -> 1283.66 | I40: =$B40 -> 1283.66 | J40: =$B40 -> 1283.66 | ... Y40: =$B40 -> 1283.66
A41: - сбытовая надбавка ГП | B41: 75.85 | C41: 75.85 | D41: 75.85 | E41: 75.85 | F41: 75.85 | G41: 75.85 | H41: 75.85 | I41: 75.85 | J41: 75.85 | K41: 75.85 | L41: 75.85 | M41: 75.85 | N41: 75.85 | O41: 75.85 | P41: 75.85 | Q41: 75.85 | R41: 75.85 | S41: 75.85 | T41: 75.85 | U41: 75.85 | V41: 75.85 | W41: 75.85 | X41: 75.85 | Y41: 75.85
A42: - инфраструктурные платежи | B42: =$B$17 -> 5.35 | C42: =$B42 -> 5.35 | D42: =$B42 -> 5.35 | E42: =$B42 -> 5.35 | F42: =$B42 -> 5.35 | G42: =$B42 -> 5.35 | H42: =$B42 -> 5.35 | I42: =$B42 -> 5.35 | J42: =$B42 -> 5.35 | ... Y42: =$B42 -> 5.35
A43: 7 | B43: =B44+B45+B46+B47 -> 3036 | C43: =C44+C45+C46+C47 -> 2867.47 | D43: =D44+D45+D46+D47 -> 2666.84 | E43: =E44+E45+E46+E47 -> 2522.11 | F43: =F44+F45+F46+F47 -> 2490.91 | G43: =G44+G45+G46+G47 -> 2580.49 | H43: =H44+H45+H46+H47 -> 2886.63 | I43: =I44+I45+I46+I47 -> 3327.86 | ... Y43: =Y44+Y45+Y46+Y47 -> 3220.17
A44: - средневзв. стоимость э/э (м) | B44: 1671.14 | C44: 1502.61 | D44: 1301.98 | E44: 1157.25 | F44: 1126.05 | G44: 1215.63 | H44: 1521.77 | I44: 1963 | J44: 2501.65 | K44: 2628.05 | L44: 2688.27 | M44: 2729.07 | N44: 2713.73 | O44: 2738.01 | P44: 2723.11 | Q44: 2756.44 | R44: 2704.53 | S44: 2819.29 | T44: 2719.06 | U44: 2682.93 | V44: 2628.49 | W44: 2645.08 | X44: 2204.5 | Y44: 1855.31
...

Sheet М_июль 6 цк
A2: ='М_июль 1 цк'!A2 -> Предельные уровни нерегулируемых цен на электрическую энергию (мощность), поставляемую АО "Мосэнергосбыт" потребителям
A3: ='М_июль 1 цк'!A3 -> с максимальной мощностью энергопринимающих устройств не менее 10 МВт
A4: ='М_июль 1 цк'!A4 -> г. Москва
A5: ='М_июль 1 цк'!A5 -> Июль 2025 г.
A7: VI. Шестая ценовая категория для объемов покупки электрической энергии (мощности), в отношении которых за расчетный период осуществляются почасовое планирование и учет, а стоимость услуг по передаче электрической энергии определяется по тарифу на услуги по передаче электрической энергии в двухставочном выражении
A9: 1.1. Ставка за электрическую энергию предельного уровня нерегулируемых цен для абонентов группы "Иные прочие потребители", рублей/МВт∙ч без НДС
A11: Дата | B11: Ставка для фактических почасовых объемов покупки электрической энергии, отпущенных на уровне напряжения ВН
B12: 0:00-1:00 | C12: 1:00-2:00 | D12: 2:00-3:00 | E12: 3:00-4:00 | F12: 4:00-5:00 | G12: 5:00-6:00 | H12: 6:00-7:00 | I12: 7:00-8:00 | J12: 8:00-9:00 | K12: 9:00-10:00 | L12: 10:00-11:00 | M12: 11:00-12:00 | N12: 12:00-13:00 | O12: 13:00-14:00 | P12: 14:00-15:00 | Q12: 15:00-16:00 | R12: 16:00-17:00 | S12: 17:00-18:00 | T12: 18:00-19:00 | U12: 19:00-20:00 | V12: 20:00-21:00 | W12: 21:00-22:00 | X12: 22:00-23:00 | Y12: 23:00-0:00
A13: 1 | B13: =B14+B15+B16+B17 -> 1790.64 | C13: =C14+C15+C16+C17 -> 1522.1 | D13: =D14+D15+D16+D17 -> 1407.02 | E13: =E14+E15+E16+E17 -> 1306.22 | F13: =F14+F15+F16+F17 -> 1328.29 | G13: =G14+G15+G16+G17 -> 1613.58 | H13: =H14+H15+H16+H17 -> 1738.81 | I13: =I14+I15+I16+I17 -> 2190.67 | ... Y13: =Y14+Y15+Y16+Y17 -> 2212.78
A14: - средневзв. стоимость э/э (м) | B14: 1628.86 | C14: 1360.32 | D14: 1245.24 | E14: 1144.44 | F14: 1166.51 | G14: 1451.8 | H14: 1577.03 | I14: 2028.89 | J14: 2529.56 | K14: 2667.84 | L14: 2730.2 | M14: 2729.08 | N14: 2714.65 | O14: 2724.92 | P14: 2753.98 | Q14: 2768.72 | R14: 2747.79 | S14: 2753.91 | T14: 2732.01 | U14: 2682.67 | V14: 2648.86 | W14: 2621.29 | X14: 2312.02 | Y14: 2051
A15: - услуги по передаче | B15: 80.58 | C15: =$B15 -> 80.58 | D15: =$B15 -> 80.58 | E15: =$B15 -> 80.58 | F15: =$B15 -> 80.58 | G15: =$B15 -> 80.58 | H15: =$B15 -> 80.58 | I15: =$B15 -> 80.58 | J15: =$B15 -> 80.58 | ... Y15: =$B15 -> 80.58
A16: - сбытовая надбавка ГП | B16: 75.85 | C16: 75.85 | D16: 75.85 | E16: 75.85 | F16: 75.85 | G16: 75.85 | H16: 75.85 | I16: 75.85 | J16: 75.85 | K16: 75.85 | L16: 75.85 | M16: 75.85 | N16: 75.85 | O16: 75.85 | P16: 75.85 | Q16: 75.85 | R16: 75.85 | S16: 75.85 | T16: 75.85 | U16: 75.85 | V16: 75.85 | W16: 75.85 | X16: 75.85 | Y16: 75.85
A17: - инфраструктурные платежи | B17: 5.35 | C17: =$B17 -> 5.35 | D17: =$B17 -> 5.35 | E17: =$B17 -> 5.35 | F17: =$B17 -> 5.35 | G17: =$B17 -> 5.35 | H17: =$B17 -> 5.35 | I17: =$B17 -> 5.35 | J17: =$B17 -> 5.35 | ... Y17: =$B17 -> 5.35
A18: 2 | B18: =B19+B20+B21+B22 -> 1835.99 | C18: =C19+C20+C21+C22 -> 1676.01 | D18: =D19+D20+D21+D22 -> 1592.36 | E18: =E19+E20+E21+E22 -> 1376.86 | F18: =F19+F20+F21+F22 -> 1471.17 | G18: =G19+G20+G21+G22 -> 1672.22 | H18: =H19+H20+H21+H22 -> 1754.32 | I18: =I19+I20+I21+I22 -> 2241.35 | ... Y18: =Y19+Y20+Y21+Y22 -> 2147.39
A19: - средневзв. стоимость э/э (м) | B19: 1674.21 | C19: 1514.23 | D19: 1430.58 | E19: 1215.08 | F19: 1309.39 | G19: 1510.44 | H19: 1592.54 | I19: 2079.57 | J19: 2692.19 | K19: 2789.44 | L19: 2822.69 | M19: 2813.51 | N19: 2828.33 | O19: 2858.33 | P19: 2859.57 | Q19: 2849.01 | R19: 2822.57 | S19: 2803.02 | T19: 2792.13 | U19: 2764.19 | V19: 2733.69 | W19: 2712.26 | X19: 2430.41 | Y19: 1985.61
A20: - услуги по передаче | B20: =$B$15 -> 80.58 | C20: =$B20 -> 80.58 | D20: =$B20 -> 80.58 | E20: =$B20 -> 80.58 | F20: =$B20 -> 80.58 | G20: =$B20 -> 80.58 | H20: =$B20 -> 80.58 | I20: =$B20 -> 80.58 | J20: =$B20 -> 80.58 | ... Y20: =$B20 -> 80.58
A21: - сбытовая надбавка ГП | B21: 75.85 | C21: 75.85 | D21: 75.85 | E21: 75.85 | F21: 75.85 | G21: 75.85 | H21: 75.85 | I21: 75.85 | J21: 75.85 | K21: 75.85 | L21: 75.85 | M21: 75.85 | N21: 75.85 | O21: 75.85 | P21: 75.85 | Q21: 75.85 | R21: 75.85 | S21: 75.85 | T21: 75.85 | U21: 75.85 | V21: 75.85 | W21: 75.85 | X21: 75.85 | Y21: 75.85
A22: - инфраструктурные платежи | B22: =$B$17 -> 5.35 | C22: =$B22 -> 5.35 | D22: =$B22 -> 5.35 | E22: =$B22 -> 5.35 | F22: =$B22 -> 5.35 | G22: =$B22 -> 5.35 | H22: =$B22 -> 5.35 | I22: =$B22 -> 5.35 | J22: =$B22 -> 5.35 | ... Y22: =$B22 -> 5.35
A23: 3 | B23: =B24+B25+B26+B27 -> 1717.91 | C23: =C24+C25+C26+C27 -> 1559.72 | D23: =D24+D25+D26+D27 -> 1436.53 | E23: =E24+E25+E26+E27 -> 1320.83 | F23: =F24+F25+F26+F27 -> 1332.44 | G23: =G24+G25+G26+G27 -> 1557.9 | H23: =H24+H25+H26+H27 -> 1701.86 | I23: =I24+I25+I26+I27 -> 2156.05 | ... Y23: =Y24+Y25+Y26+Y27 -> 2135.67
A24: - средневзв. стоимость э/э (м) | B24: 1556.13 | C24: 1397.94 | D24: 1274.75 | E24: 1159.05 | F24: 1170.66 | G24: 1396.12 | H24: 1540.08 | I24: 1994.27 | J24: 2544.78 | K24: 2584.11 | L24: 2626.41 | M24: 2659.13 | N24: 2652.3 | O24: 2636.86 | P24: 2858.16 | Q24: 2926.75 | R24: 2869.94 | S24: 2673.56 | T24: 2743.09 | U24: 2636.57 | V24: 2682.12 | W24: 2663.22 | X24: 2402.89 | Y24: 1973.89
A25: - услуги по передаче | B25: =$B$15 -> 80.58 | C25: =$B25 -> 80.58 | D25: =$B25 -> 80.58 | E25: =$B25 -> 80.58 | F25: =$B25 -> 80.58 | G25: =$B25 -> 80.58 | H25: =$B25 -> 80.58 | I25: =$B25 -> 80.58 | J25: =$B25 -> 80.58 | ... Y25: =$B25 -> 80.58
A26: - сбытовая надбавка ГП | B26: 75.85 | C26: 75.85 | D26: 75.85 | E26: 75.85 | F26: 75.85 | G26: 75.85 | H26: 75.85 | I26: 75.85 | J26: 75.85 | K26: 75.85 | L26: 75.85 | M26: 75.85 | N26: 75.85 | O26: 75.85 | P26: 75.85 | Q26: 75.85 | R26: 75.85 | S26: 75.85 | T26: 75.85 | U26: 75.85 | V26: 75.85 | W26: 75.85 | X26: 75.85 | Y26: 75.85
A27: - инфраструктурные платежи | B27: =$B$17 -> 5.35 | C27: =$B27 -> 5.35 | D27: =$B27 -> 5.35 | E27: =$B27 -> 5.35 | F27: =$B27 -> 5.35 | G27: =$B27 -> 5.35 | H27: =$B27 -> 5.35 | I27: =$B27 -> 5.35 | J27: =$B27 -> 5.35 | ... Y27: =$B27 -> 5.35
A28: 4 | B28: =B29+B30+B31+B32 -> 1808.53 | C28: =C29+C30+C31+C32 -> 1588.5 | D28: =D29+D30+D31+D32 -> 1443.05 | E28: =E29+E30+E31+E32 -> 1313.77 | F28: =F29+F30+F31+F32 -> 1330.26 | G28: =G29+G30+G31+G32 -> 1562.81 | H28: =H29+H30+H31+H32 -> 1714.89 | I28: =I29+I30+I31+I32 -> 2177.51 | ... Y28: =Y29+Y30+Y31+Y32 -> 2192.51
A29: - средневзв. стоимость э/э (м) | B29: 1646.75 | C29: 1426.72 | D29: 1281.27 | E29: 1151.99 | F29: 1168.48 | G29: 1401.03 | H29: 1553.11 | I29: 2015.73 | J29: 2553.88 | K29: 2673.17 | L29: 2626.61 | M29: 2625.16 | N29: 2692.98 | O29: 2624.48 | P29: 2769.95 | Q29: 2822.13 | R29: 2803.3 | S29: 2780.13 | T29: 2766.9 | U29: 2634.11 | V29: 2616.68 | W29: 2693.6 | X29: 2496.58 | Y29: 2030.73
A30: - услуги по передаче | B30: =$B$15 -> 80.58 | C30: =$B30 -> 80.58 | D30: =$B30 -> 80.58 | E30: =$B30 -> 80.58 | F30: =$B30 -> 80.58 | G30: =$B30 -> 80.58 | H30: =$B30 -> 80.58 | I30: =$B30 -> 80.58 | J30: =$B30 -> 80.58 | ... Y30: =$B30 -> 80.58
A31: - сбытовая надбавка ГП | B31: 75.85 | C31: 75.85 | D31: 75.85 | E31: 75.85 | F31: 75.85 | G31: 75.85 | H31: 75.85 | I31: 75.85 | J31: 75.85 | K31: 75.85 | L31: 75.85 | M31: 75.85 | N31: 75.85 | O31: 75.85 | P31: 75.85 | Q31: 75.85 | R31: 75.85 | S31: 75.85 | T31: 75.85 | U31: 75.85 | V31: 75.85 | W31: 75.85 | X31: 75.85 | Y31: 75.85
A32: - инфраструктурные платежи | B32: =$B$17 -> 5.35 | C32: =$B32 -> 5.35 | D32: =$B32 -> 5.35 | E32: =$B32 -> 5.35 | F32: =$B32 -> 5.35 | G32: =$B32 -> 5.35 | H32: =$B32 -> 5.35 | I32: =$B32 -> 5.35 | J32: =$B32 -> 5.35 | ... Y32: =$B32 -> 5.35
A33: 5 | B33: =B34+B35+B36+B37 -> 1900.37 | C33: =C34+C35+C36+C37 -> 1666.14 | D33: =D34+D35+D36+D37 -> 1559.09 | E33: =E34+E35+E36+E37 -> 1415.95 | F33: =F34+F35+F36+F37 -> 1357.66 | G33: =G34+G35+G36+G37 -> 1348.71 | H33: =H34+H35+H36+H37 -> 1451.87 | I33: =I34+I35+I36+I37 -> 1816.03 | ... Y33: =Y34+Y35+Y36+Y37 -> 2128.17
A34: - средневзв. стоимость э/э (м) | B34: 1738.59 | C34: 1504.36 | D34: 1397.31 | E34: 1254.17 | F34: 1195.88 | G34: 1186.93 | H34: 1290.09 | I34: 1654.25 | J34: 2120.14 | K34: 2356.02 | L34: 2424.84 | M34: 2454.2 | N34: 2449.57 | O34: 2453.65 | P34: 2450.03 | Q34: 2512.33 | R34: 2520.61 | S34: 2485.92 | T34: 2465.87 | U34: 2437.81 | V34: 2435.72 | W34: 2452.81 | X34: 2154.71 | Y34: 1966.39
A35: - услуги по передаче | B35: =$B$15 -> 80.58 | C35: =$B35 -> 80.58 | D35: =$B35 -> 80.58 | E35: =$B35 -> 80.58 | F35: =$B35 -> 80.58 | G35: =$B35 -> 80.58 | H35: =$B35 -> 80.58 | I35: =$B35 -> 80.58 | J35: =$B35 -> 80.58 | ... Y35: =$B35 -> 80.58
A36: - сбытовая надбавка ГП | B36: 75.85 | C36: 75.85 | D36: 75.85 | E36: 75.85 | F36: 75.85 | G36: 75.85 | H36: 75.85 | I36: 75.85 | J36: 75.85 | K36: 75.85 | L36: 75.85 | M36: 75.85 | N36: 75.85 | O36: 75.85 | P36: 75.85 | Q36: 75.85 | R36: 75.85 | S36: 75.85 | T36: 75.85 | U36: 75.85 | V36: 75.85 | W36: 75.85 | X36: 75.85 | Y36: 75.85
A37: - инфраструктурные платежи | B37: =$B$17 -> 5.35 | C37: =$B37 -> 5.35 | D37: =$B37 -> 5.35 | E37: =$B37 -> 5.35 | F37: =$B37 -> 5.35 | G37: =$B37 -> 5.35 | H37: =$B37 -> 5.35 | I37: =$B37 -> 5.35 | J37: =$B37 -> 5.35 | ... Y37: =$B37 -> 5.35
A38: 6 | B38: =B39+B40+B41+B42 -> 1908.66 | C38: =C39+C40+C41+C42 -> 1654.59 | D38: =D39+D40+D41+D42 -> 1533.61 | E38: =E39+E40+E41+E42 -> 1347.98 | F38: =F39+F40+F41+F42 -> 1290.49 | G38: =G39+G40+G41+G42 -> 1289.42 | H38: =H39+H40+H41+H42 -> 1234.17 | I38: =I39+I40+I41+I42 -> 1663.02 | ... Y38: =Y39+Y40+Y41+Y42 -> 1989.55
A39: - средневзв. стоимость э/э (м) | B39: 1746.88 | C39: 1492.81 | D39: 1371.83 | E39: 1186.2 | F39: 1128.71 | G39: 1127.64 | H39: 1072.39 | I39: 1501.24 | J39: 1906.15 | K39: 2244.04 | L39: 2381.13 | M39: 2381.09 | N39: 2383.85 | O39: 2390.93 | P39: 2395.78 | Q39: 2397.59 | R39: 2450.8 | S39: 2436.66 | T39: 2434.99 | U39: 2418.9 | V39: 2418.43 | W39: 2414.63 | X39: 2170.25 | Y39: 1827.77
A40: - услуги по передаче | B40: =$B$15 -> 80.58 | C40: =$B40 -> 80.58 | D40: =$B40 -> 80.58 | E40: =$B40 -> 80.58 | F40: =$B40 -> 80.58 | G40: =$B40 -> 80.58 | H40: =$B40 -> 80.58 | I40: =$B40 -> 80.58 | J40: =$B40 -> 80.58 | ... Y40: =$B40 -> 80.58
A41: - сбытовая надбавка ГП | B41: 75.85 | C41: 75.85 | D41: 75.85 | E41: 75.85 | F41: 75.85 | G41: 75.85 | H41: 75.85 | I41: 75.85 | J41: 75.85 | K41: 75.85 | L41: 75.85 | M41: 75.85 | N41: 75.85 | O41: 75.85 | P41: 75.85 | Q41: 75.85 | R41: 75.85 | S41: 75.85 | T41: 75.85 | U41: 75.85 | V41: 75.85 | W41: 75.85 | X41: 75.85 | Y41: 75.85
A42: - инфраструктурные платежи | B42: =$B$17 -> 5.35 | C42: =$B42 -> 5.35 | D42: =$B42 -> 5.35 | E42: =$B42 -> 5.35 | F42: =$B42 -> 5.35 | G42: =$B42 -> 5.35 | H42: =$B42 -> 5.35 | I42: =$B42 -> 5.35 | J42: =$B42 -> 5.35 | ... Y42: =$B42 -> 5.35
A43: 7 | B43: =B44+B45+B46+B47 -> 1832.92 | C43: =C44+C45+C46+C47 -> 1664.39 | D43: =D44+D45+D46+D47 -> 1463.76 | E43: =E44+E45+E46+E47 -> 1319.03 | F43: =F44+F45+F46+F47 -> 1287.83 | G43: =G44+G45+G46+G47 -> 1377.41 | H43: =H44+H45+H46+H47 -> 1683.55 | I43: =I44+I45+I46+I47 -> 2124.78 | ... Y43: =Y44+Y45+Y46+Y47 -> 2017.09
A44: - средневзв. стоимость э/э (м) | B44: 1671.14 | C44: 1502.61 | D44: 1301.98 | E44: 1157.25 | F44: 1126.05 | G44: 1215.63 | H44: 1521.77 | I44: 1963 | J44: 2501.65 | K44: 2628.05 | L44: 2688.27 | M44: 2729.07 | N44: 2713.73 | O44: 2738.01 | P44: 2723.11 | Q44: 2756.44 | R44: 2704.53 | S44: 2819.29 | T44: 2719.06 | U44: 2682.93 | V44: 2628.49 | W44: 2645.08 | X44: 2204.5 | Y44: 1855.31
...

Sheet О_июль 1 цк
A2: Предельные уровни нерегулируемых цен на электрическую энергию (мощность), поставляемую АО "Мосэнергосбыт" потребителям
A3: с максимальной мощностью энергопринимающих устройств не менее 10 МВт
A4: Московская область
A5: ='М_июль 1 цк'!A5:F5 -> Июль 2025 г.
A7: I. Первая ценовая категория для объемов покупки электрической энергии (мощности), учет которых осуществляется в целом за расчетный период
A9: 1. Предельный уровень нерегулируемых цен, руб./МВт∙ч без НДС
A11: № п/п | B11: Группа потребителей | C11: Уровень напряжения
C12: ВН | D12: СН I | E12: СН II | F12: НН
A13: 1.1. | B13: Прочие потребители
A14: 1.1.1. | B14: Иные прочие потребители | C14: =C15+C16+C17+C19+C18 -> 5638.34 | D14: =D15+D16+D17+D19+D18 -> 6491.32 | E14: =E15+E16+E17+E19+E18 -> 7021.03 | F14: =F15+F16+F17+F19+F18 -> 7975.53
B15: - средневзв. стоимость э/э (м) | C15: 3602.47 | D15: =C15 -> 3602.47 | E15: =C15 -> 3602.47 | F15: =C15 -> 3602.47
B16: - услуги по передаче | C16: 1922.63 | D16: 2775.61 | E16: 3305.32 | F16: 4259.82
B17: - сбытовая надбавка ГП | C17: 106.82 | D17: =C17 -> 106.82 | E17: =C17 -> 106.82 | F17: =C17 -> 106.82
B18: - плата за услуги по управлению изменением режима потребления электрической энергии | C18: 1.07 | D18: 1.07 | E18: 1.07 | F18: 1.07
B19: - инфраструктурные платежи | C19: 5.35 | D19: =C19 -> 5.35 | E19: =C19 -> 5.35 | F19: =C19 -> 5.35
A20: 1.1.2. | B20: Потребители, рассчитывающиеся по договорам купли-продажи | C20: =C21+C22+C24+C23 -> 3715.71 | D20: =D21+D22+D24+D23 -> 3715.71 | E20: =E21+E22+E24+E23 -> 3715.71 | F20: =F21+F22+F24+F23 -> 3715.71
B21: - средневзв. стоимость э/э (м) | C21: =C15 -> 3602.47 | D21: =C21 -> 3602.47 | E21: =C21 -> 3602.47 | F21: =C21 -> 3602.47
B22: - сбытовая надбавка ГП | C22: =C17 -> 106.82 | D22: =C22 -> 106.82 | E22: =C22 -> 106.82 | F22: =C22 -> 106.82
B23: - плата за услуги по управлению изменением режима потребления электрической энергии | C23: 1.07 | D23: 1.07 | E23: 1.07 | F23: 1.07
B24: - инфраструктурные платежи | C24: =C19 -> 5.35 | D24: =C24 -> 5.35 | E24: =C24 -> 5.35 | F24: =C24 -> 5.35
A27: 2. | B27: Средневзвешенная нерегулируемая цена на электрическую энергию (мощность), используемая для расчета предельного уровня нерегулируемых цен для первой ценовой категории, без НДС, руб./МВт∙ч | E27: ='М_июль 1 цк'!E27 -> 3602.47
A28: 3. | B28: Составляющие расчета средневзвешенной нерегулируемой цены на электрическую энергию (мощность), используемой для расчета предельного уровня нерегулируемых цен для первой ценовой категории:
A29: а) | B29: средневзвешенная нерегулируемая цена на электрическую энергию на оптовом рынке, руб./МВт∙ч | E29: ='М_июль 1 цк'!E29 -> 2324,93
A30: б) | B30: средневзвешенная нерегулируемая цена на мощность на оптовом рынке, руб./МВт | E30: ='М_июль 1 цк'!E30 -> 937404,45
A31: в) | B31: коэффициент оплаты мощности потребителями (покупателями), осуществляющими расчеты по первой ценовой категории, 1/час | E31: ='М_июль 1 цк'!E31 -> 0.0013628526
A32: г) | B32: объем фактического пикового потребления гарантирующего поставщика на оптовом рынке, МВт | E32: ='М_июль 1 цк'!E32 -> 12653.047
A33: д) | B33: величина мощности, соответствующей покупке электрической энергии гарантирующим поставщиком у производителей электрической энергии (мощности) на розничных рынках, МВт | E33: ='М_июль 1 цк'!E33 -> 8.244
A34: е) | B34: сумма величин мощности, оплачиваемой на розничном рынке потребителями (покупателями), осуществляющими расчеты по второй - шестой ценовым категориям, МВт | E34: ='М_июль 1 цк'!E34 -> 5425.2309
B35: в том числе:
B36: – по второй ценовой категории, МВт | E36: ='М_июль 1 цк'!E36 -> 31.37
B37: – по третьей ценовой категории, МВт | E37: ='М_июль 1 цк'!E37 -> 3055.548
B38: – по четвертой ценовой категории, МВт | E38: ='М_июль 1 цк'!E38 -> 1954.9029
B39: – по пятой ценовой категории, МВт | E39: ='М_июль 1 цк'!E39 -> 24.143838
B40: – по шестой ценовой категории, МВт | E40: ='М_июль 1 цк'!E40 -> 359.26613
A41: ж) | B41: объем потребления мощности населением и приравненными к нему категориями потребителей, МВт | E41: ='М_июль 1 цк'!E41 -> 3942.223
A42: з) | B42: объем потребления электрической энергии потребителями (покупателями), осуществляющими расчеты по второй ценовой категории, МВт∙ч | E42: ='М_июль 1 цк'!E42 -> 13059.656
B43: в том числе:
B44: для трех зон суток, МВт∙ч | E44: ='М_июль 1 цк'!E44 -> 10179.74
B45: – по ночной зоне суток, МВт∙ч | E45: ='М_июль 1 цк'!E45 -> 3314.096
B46: – по полупиковой зоне суток, МВт∙ч | E46: ='М_июль 1 цк'!E46 -> 4121.4071
...

Sheet О_июль 2 цк
A2: ='О_июль 1 цк'!A2 -> Предельные уровни нерегулируемых цен на электрическую энергию (мощность), поставляемую АО "Мосэнергосбыт" потребителям
A3: ='О_июль 1 цк'!A3 -> с максимальной мощностью энергопринимающих устройств не менее 10 МВт
A4: ='О_июль 1 цк'!A4 -> Московская область
A5: ='О_июль 1 цк'!A5 -> Июль 2025 г.
A7: II. Вторая ценовая категория для объемов покупки электрической энергии (мощности), учет которых осуществляется по зонам суток расчетного периода
A9: 1. Предельный уровень нерегулируемых цен для трех зон суток, руб./МВт∙ч без НДС
A11: № п/п | B11: Группа потребителей | C11: Уровень напряжения
C12: ВН | D12: СН I | E12: СН II | F12: НН
A13: 1.1. | B13: Прочие потребители
A14: 1.1.1. | B14: Иные прочие потребители
